[2023-12-19T16:59:09.934+0000] {taskinstance.py:1157} INFO - Dependencies all met for dep_context=non-requeueable deps ti=<TaskInstance: gx.gx_validate_pg manual__2023-12-19T16:59:03.896324+00:00 [queued]>
[2023-12-19T16:59:09.944+0000] {taskinstance.py:1157} INFO - Dependencies all met for dep_context=requeueable deps ti=<TaskInstance: gx.gx_validate_pg manual__2023-12-19T16:59:03.896324+00:00 [queued]>
[2023-12-19T16:59:09.945+0000] {taskinstance.py:1359} INFO - Starting attempt 1 of 1
[2023-12-19T16:59:09.955+0000] {taskinstance.py:1380} INFO - Executing <Task(GreatExpectationsOperator): gx_validate_pg> on 2023-12-19 16:59:03.896324+00:00
[2023-12-19T16:59:09.969+0000] {standard_task_runner.py:57} INFO - Started process 703 to run task
[2023-12-19T16:59:09.979+0000] {standard_task_runner.py:84} INFO - Running: ['***', 'tasks', 'run', 'gx', 'gx_validate_pg', 'manual__2023-12-19T16:59:03.896324+00:00', '--job-id', '10', '--raw', '--subdir', 'DAGS_FOLDER/gx.py', '--cfg-path', '/tmp/tmp6ocfgshv']
[2023-12-19T16:59:09.982+0000] {standard_task_runner.py:85} INFO - Job 10: Subtask gx_validate_pg
[2023-12-19T16:59:10.093+0000] {task_command.py:415} INFO - Running <TaskInstance: gx.gx_validate_pg manual__2023-12-19T16:59:03.896324+00:00 [running]> on host d2178d55ea0c
[2023-12-19T16:59:10.204+0000] {taskinstance.py:1660} INFO - Exporting env vars: AIRFLOW_CTX_DAG_OWNER='***' AIRFLOW_CTX_DAG_ID='gx' AIRFLOW_CTX_TASK_ID='gx_validate_pg' AIRFLOW_CTX_EXECUTION_DATE='2023-12-19T16:59:03.896324+00:00' AIRFLOW_CTX_TRY_NUMBER='1' AIRFLOW_CTX_DAG_RUN_ID='manual__2023-12-19T16:59:03.896324+00:00'
[2023-12-19T16:59:10.206+0000] {great_expectations.py:570} INFO - Running validation with Great Expectations...
[2023-12-19T16:59:10.206+0000] {great_expectations.py:572} INFO - Instantiating Data Context...
[2023-12-19T16:59:10.224+0000] {taskinstance.py:1935} ERROR - Task failed with exception
Traceback (most recent call last):
  File "/home/airflow/.local/lib/python3.8/site-packages/great_expectations_provider/operators/great_expectations.py", line 574, in execute
    self.build_runtime_datasources()
  File "/home/airflow/.local/lib/python3.8/site-packages/great_expectations_provider/operators/great_expectations.py", line 476, in build_runtime_datasources
    self.conn = BaseHook.get_connection(self.conn_id) if self.conn_id else None
  File "/home/airflow/.local/lib/python3.8/site-packages/airflow/hooks/base.py", line 72, in get_connection
    conn = Connection.get_connection_from_secrets(conn_id)
  File "/home/airflow/.local/lib/python3.8/site-packages/airflow/models/connection.py", line 477, in get_connection_from_secrets
    raise AirflowNotFoundException(f"The conn_id `{conn_id}` isn't defined")
airflow.exceptions.AirflowNotFoundException: The conn_id `postgres_default` isn't defined
[2023-12-19T16:59:10.229+0000] {taskinstance.py:1398} INFO - Marking task as FAILED. dag_id=gx, task_id=gx_validate_pg, execution_date=20231219T165903, start_date=20231219T165909, end_date=20231219T165910
[2023-12-19T16:59:10.239+0000] {standard_task_runner.py:104} ERROR - Failed to execute job 10 for task gx_validate_pg (The conn_id `postgres_default` isn't defined; 703)
[2023-12-19T16:59:10.290+0000] {local_task_job_runner.py:228} INFO - Task exited with return code 1
[2023-12-19T16:59:10.305+0000] {taskinstance.py:2776} INFO - 0 downstream tasks scheduled from follow-on schedule check
