[2023-12-20T15:01:34.034+0000] {taskinstance.py:1157} INFO - Dependencies all met for dep_context=non-requeueable deps ti=<TaskInstance: gx.gx_validate_pg manual__2023-12-20T15:01:27.351726+00:00 [queued]>
[2023-12-20T15:01:34.061+0000] {taskinstance.py:1157} INFO - Dependencies all met for dep_context=requeueable deps ti=<TaskInstance: gx.gx_validate_pg manual__2023-12-20T15:01:27.351726+00:00 [queued]>
[2023-12-20T15:01:34.063+0000] {taskinstance.py:1359} INFO - Starting attempt 1 of 1
[2023-12-20T15:01:34.134+0000] {taskinstance.py:1380} INFO - Executing <Task(GreatExpectationsOperator): gx_validate_pg> on 2023-12-20 15:01:27.351726+00:00
[2023-12-20T15:01:34.163+0000] {standard_task_runner.py:57} INFO - Started process 2484 to run task
[2023-12-20T15:01:34.167+0000] {standard_task_runner.py:84} INFO - Running: ['***', 'tasks', 'run', 'gx', 'gx_validate_pg', 'manual__2023-12-20T15:01:27.351726+00:00', '--job-id', '15', '--raw', '--subdir', 'DAGS_FOLDER/gx.py', '--cfg-path', '/tmp/tmpf3kdt4t_']
[2023-12-20T15:01:34.168+0000] {standard_task_runner.py:85} INFO - Job 15: Subtask gx_validate_pg
[2023-12-20T15:01:34.239+0000] {task_command.py:415} INFO - Running <TaskInstance: gx.gx_validate_pg manual__2023-12-20T15:01:27.351726+00:00 [running]> on host d2178d55ea0c
[2023-12-20T15:01:34.442+0000] {taskinstance.py:1660} INFO - Exporting env vars: AIRFLOW_CTX_DAG_OWNER='***' AIRFLOW_CTX_DAG_ID='gx' AIRFLOW_CTX_TASK_ID='gx_validate_pg' AIRFLOW_CTX_EXECUTION_DATE='2023-12-20T15:01:27.351726+00:00' AIRFLOW_CTX_TRY_NUMBER='1' AIRFLOW_CTX_DAG_RUN_ID='manual__2023-12-20T15:01:27.351726+00:00'
[2023-12-20T15:01:34.443+0000] {great_expectations.py:570} INFO - Running validation with Great Expectations...
[2023-12-20T15:01:34.443+0000] {great_expectations.py:572} INFO - Instantiating Data Context...
[2023-12-20T15:01:34.466+0000] {base.py:73} INFO - Using connection ID 'postgres_default' for task execution.
[2023-12-20T15:01:34.497+0000] {warnings.py:109} WARNING - /home/***/.local/lib/python3.8/site-packages/great_expectations/data_context/data_context/base_data_context.py:158: DeprecationWarning: DataContext and BaseDataContext are deprecated as of v0.17.10 and will be removed in v0.20. Please use gx.get_context instead.
  warnings.warn(

[2023-12-20T15:01:34.519+0000] {warnings.py:109} WARNING - /home/***/.local/lib/python3.8/site-packages/great_expectations/data_context/data_context/serializable_data_context.py:225: UserWarning: Warning. An existing `great_expectations.yml` was found here: /opt/***/include/gx.
    - No action was taken.
  warnings.warn(message)

[2023-12-20T15:01:34.520+0000] {warnings.py:109} WARNING - /home/***/.local/lib/python3.8/site-packages/great_expectations/data_context/data_context/serializable_data_context.py:235: UserWarning: Warning. An existing `config_variables.yml` was found here: /opt/***/include/gx/uncommitted.
    - No action was taken.
  warnings.warn(message)

[2023-12-20T15:01:34.526+0000] {file_data_context.py:222} INFO - FileDataContext loading fluent config
[2023-12-20T15:01:34.529+0000] {config.py:185} INFO - Loading 'datasources' ->
[]
[2023-12-20T15:01:34.595+0000] {great_expectations.py:585} INFO - Creating Checkpoint...
[2023-12-20T15:01:34.598+0000] {great_expectations.py:604} INFO - Running Checkpoint...
[2023-12-20T15:01:34.621+0000] {taskinstance.py:1935} ERROR - Task failed with exception
Traceback (most recent call last):
  File "/home/airflow/.local/lib/python3.8/site-packages/great_expectations_provider/operators/great_expectations.py", line 607, in execute
    result = self.checkpoint.run(batch_request=self.batch_request)
  File "/home/airflow/.local/lib/python3.8/site-packages/great_expectations/core/usage_statistics/usage_statistics.py", line 260, in usage_statistics_wrapped_method
    result = func(*args, **kwargs)
  File "/home/airflow/.local/lib/python3.8/site-packages/great_expectations/checkpoint/checkpoint.py", line 315, in run
    self._run_validation(
  File "/home/airflow/.local/lib/python3.8/site-packages/great_expectations/checkpoint/checkpoint.py", line 480, in _run_validation
    validator: Validator = self._validator or self.data_context.get_validator(
  File "/home/airflow/.local/lib/python3.8/site-packages/great_expectations/data_context/data_context/abstract_data_context.py", line 2336, in get_validator
    expectation_suite = self.get_expectation_suite(
  File "/home/airflow/.local/lib/python3.8/site-packages/great_expectations/data_context/data_context/abstract_data_context.py", line 3008, in get_expectation_suite
    dict, self.expectations_store.get(key)
  File "/home/airflow/.local/lib/python3.8/site-packages/great_expectations/data_context/store/expectations_store.py", line 210, in get
    return super().get(key)  # type: ignore[return-value]
  File "/home/airflow/.local/lib/python3.8/site-packages/great_expectations/data_context/store/store.py", line 210, in get
    return self.deserialize(value)
  File "/home/airflow/.local/lib/python3.8/site-packages/great_expectations/data_context/store/expectations_store.py", line 236, in deserialize
    return self._expectationSuiteSchema.loads(value)
  File "/home/airflow/.local/lib/python3.8/site-packages/marshmallow/schema.py", line 756, in loads
    return self.load(data, many=many, partial=partial, unknown=unknown)
  File "/home/airflow/.local/lib/python3.8/site-packages/marshmallow/schema.py", line 722, in load
    return self._do_load(
  File "/home/airflow/.local/lib/python3.8/site-packages/marshmallow/schema.py", line 909, in _do_load
    raise exc
marshmallow.exceptions.ValidationError: {'expectations': {0: {'args': ['Unknown field.']}}}
[2023-12-20T15:01:34.686+0000] {taskinstance.py:1398} INFO - Marking task as FAILED. dag_id=gx, task_id=gx_validate_pg, execution_date=20231220T150127, start_date=20231220T150134, end_date=20231220T150134
[2023-12-20T15:01:34.725+0000] {standard_task_runner.py:104} ERROR - Failed to execute job 15 for task gx_validate_pg ({'expectations': {0: {'args': ['Unknown field.']}}}; 2484)
[2023-12-20T15:01:34.774+0000] {local_task_job_runner.py:228} INFO - Task exited with return code 1
[2023-12-20T15:01:34.881+0000] {taskinstance.py:2776} INFO - 0 downstream tasks scheduled from follow-on schedule check
