[2023-12-19T16:39:12.010+0000] {taskinstance.py:1157} INFO - Dependencies all met for dep_context=non-requeueable deps ti=<TaskInstance: gx.create_table_pg manual__2023-12-19T16:39:04.205057+00:00 [queued]>
[2023-12-19T16:39:12.020+0000] {taskinstance.py:1157} INFO - Dependencies all met for dep_context=requeueable deps ti=<TaskInstance: gx.create_table_pg manual__2023-12-19T16:39:04.205057+00:00 [queued]>
[2023-12-19T16:39:12.020+0000] {taskinstance.py:1359} INFO - Starting attempt 1 of 1
[2023-12-19T16:39:12.035+0000] {taskinstance.py:1380} INFO - Executing <Task(PostgresOperator): create_table_pg> on 2023-12-19 16:39:04.205057+00:00
[2023-12-19T16:39:12.042+0000] {standard_task_runner.py:57} INFO - Started process 392 to run task
[2023-12-19T16:39:12.049+0000] {standard_task_runner.py:84} INFO - Running: ['***', 'tasks', 'run', 'gx', 'create_table_pg', 'manual__2023-12-19T16:39:04.205057+00:00', '--job-id', '7', '--raw', '--subdir', 'DAGS_FOLDER/gx.py', '--cfg-path', '/tmp/tmp7_67sgjq']
[2023-12-19T16:39:12.051+0000] {standard_task_runner.py:85} INFO - Job 7: Subtask create_table_pg
[2023-12-19T16:39:12.128+0000] {task_command.py:415} INFO - Running <TaskInstance: gx.create_table_pg manual__2023-12-19T16:39:04.205057+00:00 [running]> on host d2178d55ea0c
[2023-12-19T16:39:12.285+0000] {taskinstance.py:1660} INFO - Exporting env vars: AIRFLOW_CTX_DAG_OWNER='***' AIRFLOW_CTX_DAG_ID='gx' AIRFLOW_CTX_TASK_ID='create_table_pg' AIRFLOW_CTX_EXECUTION_DATE='2023-12-19T16:39:04.205057+00:00' AIRFLOW_CTX_TRY_NUMBER='1' AIRFLOW_CTX_DAG_RUN_ID='manual__2023-12-19T16:39:04.205057+00:00'
[2023-12-19T16:39:12.286+0000] {sql.py:274} INFO - Executing: 
            CREATE TABLE IF NOT EXISTS taxi (
                VendorID VARCHAR(50),
                tpep_pickup_datetime VARCHAR (50),
                tpep_dropoff_datetime VARCHAR (50),
                passenger_count DECIMAL,
                trip_distance DECIMAL,
                RatecodeID DECIMAL, 
                store_and_fwd_flag VARCHAR(50), 
                PULocationID VARCHAR(50),
                DOLocationID VARCHAR(50), 
                payment_type VARCHAR(50), 
                fare_amount DECIMAL, 
                extra DECIMAL, 
                mta_tax DECIMAL, 
                tip_amount DECIMAL, 
                tolls_amount DECIMAL, 
                improvement_surcharge VARCHAR(50),
                total_amount DECIMAL,
                congestion_surcharge DECIMAL, 
                Airport_fee DECIMAL
                );

            INSERT INTO taxi (VendorID, tpep_pickup_datetime, tpep_dropoff_datetime, passenger_count, trip_distance, RatecodeID, store_and_fwd_flag,
            PULocationID, DOLocationID, payment_type, fare_amount, extra, mta_tax, tip_amount, tolls_amount, improvement_surcharge, total_amount, congestion_surcharge,
            Airport_fee)
            VALUES ('001', 'Strawberry Order 1', 10),
                ('002', 'Strawberry Order 2', 5),
                ('003', 'Strawberry Order 3', 8),
                ('004', 'Strawberry Order 4', 3),
                ('005', 'Strawberry Order 5', 12);
            
[2023-12-19T16:39:12.305+0000] {taskinstance.py:1935} ERROR - Task failed with exception
Traceback (most recent call last):
  File "/home/airflow/.local/lib/python3.8/site-packages/airflow/providers/common/sql/operators/sql.py", line 275, in execute
    hook = self.get_db_hook()
  File "/home/airflow/.local/lib/python3.8/site-packages/airflow/providers/common/sql/operators/sql.py", line 186, in get_db_hook
    return self._hook
  File "/usr/local/lib/python3.8/functools.py", line 967, in __get__
    val = self.func(instance)
  File "/home/airflow/.local/lib/python3.8/site-packages/airflow/providers/common/sql/operators/sql.py", line 148, in _hook
    conn = BaseHook.get_connection(conn_id)
  File "/home/airflow/.local/lib/python3.8/site-packages/airflow/hooks/base.py", line 72, in get_connection
    conn = Connection.get_connection_from_secrets(conn_id)
  File "/home/airflow/.local/lib/python3.8/site-packages/airflow/models/connection.py", line 477, in get_connection_from_secrets
    raise AirflowNotFoundException(f"The conn_id `{conn_id}` isn't defined")
airflow.exceptions.AirflowNotFoundException: The conn_id `postgres_default` isn't defined
[2023-12-19T16:39:12.315+0000] {taskinstance.py:1398} INFO - Marking task as FAILED. dag_id=gx, task_id=create_table_pg, execution_date=20231219T163904, start_date=20231219T163912, end_date=20231219T163912
[2023-12-19T16:39:12.338+0000] {standard_task_runner.py:104} ERROR - Failed to execute job 7 for task create_table_pg (The conn_id `postgres_default` isn't defined; 392)
[2023-12-19T16:39:12.364+0000] {local_task_job_runner.py:228} INFO - Task exited with return code 1
[2023-12-19T16:39:12.491+0000] {taskinstance.py:2776} INFO - 0 downstream tasks scheduled from follow-on schedule check
