[2023-12-19T17:07:22.998+0000] {taskinstance.py:1157} INFO - Dependencies all met for dep_context=non-requeueable deps ti=<TaskInstance: gx.gx_validate_pg manual__2023-12-19T17:07:16.273839+00:00 [queued]>
[2023-12-19T17:07:23.007+0000] {taskinstance.py:1157} INFO - Dependencies all met for dep_context=requeueable deps ti=<TaskInstance: gx.gx_validate_pg manual__2023-12-19T17:07:16.273839+00:00 [queued]>
[2023-12-19T17:07:23.007+0000] {taskinstance.py:1359} INFO - Starting attempt 1 of 1
[2023-12-19T17:07:23.026+0000] {taskinstance.py:1380} INFO - Executing <Task(GreatExpectationsOperator): gx_validate_pg> on 2023-12-19 17:07:16.273839+00:00
[2023-12-19T17:07:23.036+0000] {standard_task_runner.py:57} INFO - Started process 841 to run task
[2023-12-19T17:07:23.040+0000] {standard_task_runner.py:84} INFO - Running: ['***', 'tasks', 'run', 'gx', 'gx_validate_pg', 'manual__2023-12-19T17:07:16.273839+00:00', '--job-id', '11', '--raw', '--subdir', 'DAGS_FOLDER/gx.py', '--cfg-path', '/tmp/tmpsyfcz3ko']
[2023-12-19T17:07:23.041+0000] {standard_task_runner.py:85} INFO - Job 11: Subtask gx_validate_pg
[2023-12-19T17:07:23.116+0000] {task_command.py:415} INFO - Running <TaskInstance: gx.gx_validate_pg manual__2023-12-19T17:07:16.273839+00:00 [running]> on host d2178d55ea0c
[2023-12-19T17:07:23.253+0000] {taskinstance.py:1660} INFO - Exporting env vars: AIRFLOW_CTX_DAG_OWNER='***' AIRFLOW_CTX_DAG_ID='gx' AIRFLOW_CTX_TASK_ID='gx_validate_pg' AIRFLOW_CTX_EXECUTION_DATE='2023-12-19T17:07:16.273839+00:00' AIRFLOW_CTX_TRY_NUMBER='1' AIRFLOW_CTX_DAG_RUN_ID='manual__2023-12-19T17:07:16.273839+00:00'
[2023-12-19T17:07:23.254+0000] {great_expectations.py:570} INFO - Running validation with Great Expectations...
[2023-12-19T17:07:23.254+0000] {great_expectations.py:572} INFO - Instantiating Data Context...
[2023-12-19T17:07:23.265+0000] {base.py:73} INFO - Using connection ID 'postgres_default' for task execution.
[2023-12-19T17:07:23.268+0000] {taskinstance.py:1935} ERROR - Task failed with exception
Traceback (most recent call last):
  File "/home/airflow/.local/lib/python3.8/site-packages/great_expectations/data_context/data_context/file_data_context.py", line 198, in _load_file_backed_project_config
    with open(path_to_yml) as data:
FileNotFoundError: [Errno 2] No such file or directory: '/opt/airflow/include/great_expectations/great_expectations.yml'

During handling of the above exception, another exception occurred:

Traceback (most recent call last):
  File "/home/airflow/.local/lib/python3.8/site-packages/great_expectations_provider/operators/great_expectations.py", line 576, in execute
    self.data_context = ge.data_context.DataContext(context_root_dir=self.data_context_root_dir)
  File "/home/airflow/.local/lib/python3.8/site-packages/great_expectations/data_context/data_context/data_context.py", line 129, in DataContext
    project_config = FileDataContext._load_file_backed_project_config(
  File "/home/airflow/.local/lib/python3.8/site-packages/great_expectations/data_context/data_context/file_data_context.py", line 210, in _load_file_backed_project_config
    raise gx_exceptions.ConfigNotFoundError()
great_expectations.exceptions.exceptions.ConfigNotFoundError: Error: No gx directory was found here!
    - Please check that you are in the correct directory or have specified the correct directory.
    - If you have never run Great Expectations in this project, please run `great_expectations init` to get started.

[2023-12-19T17:07:23.302+0000] {taskinstance.py:1398} INFO - Marking task as FAILED. dag_id=gx, task_id=gx_validate_pg, execution_date=20231219T170716, start_date=20231219T170722, end_date=20231219T170723
[2023-12-19T17:07:23.324+0000] {standard_task_runner.py:104} ERROR - Failed to execute job 11 for task gx_validate_pg (Error: No gx directory was found here!
    - Please check that you are in the correct directory or have specified the correct directory.
    - If you have never run Great Expectations in this project, please run `great_expectations init` to get started.
; 841)
[2023-12-19T17:07:23.345+0000] {local_task_job_runner.py:228} INFO - Task exited with return code 1
[2023-12-19T17:07:23.358+0000] {taskinstance.py:2776} INFO - 0 downstream tasks scheduled from follow-on schedule check
